Workbook

Sheet PIC_API_SUITE
A1: TestCaseName | B1: EndPoint | C1: Method | D1: Payload | E1: ExpectedStatusCode | F1: Expected Response | G1: Extracted Key
A2: =CONCATENATE("TC_",'API Test Inputs'!A2,"_",'API Test Inputs'!B2,"_Description:",'API Test Inputs'!E2,"_Tester:",'API Test Inputs'!C2) -> TC_1_AI_Chat_Description:verifyCreateConversation_Tester:Alok Kumar | B2: ='API Test Inputs'!D2 -> /genai/graphql | C2: ='API Test Inputs'!F2 -> POST | D2: ='API Test Inputs'!G2 -> {"query":"mutation MyMutation {\n create_conversation(\n inputs: {scope_id: \"04b7fc60-63bd-44d7-bcbf-09d1476fa0aa\", conversation_name: \"Created Conv by Automation\", conversation_id: \"{conversation_id}\", created_timestamp: \"{current_timeStamp}\", owned_by_user_id: 50395262, shared_by_user_id : 50395262}\n ) {\n data {\n conversation_id\n conv_own_emp_id\n conversation_name\n created_timestamp\n last_msg_timestamp\n scope_id\n shared_by_user_id\n }\n message\n status\n }\n}"} | E2: ='API Test Inputs'!H2 -> 200 | F2: ='API Test Inputs'!I2 -> {"data":{"create_conversation":{"data":[{"conversation_id":"{conversation_id}","conv_own_emp_id":50395262,"conversation_name":"Created Conv by Automation","scope_id":"04b7fc60-63bd-44d7-bcbf-09d1476fa0aa","shared_by_user_id":50395262}],"message":"Conversation created successfully","status":"Created"}}} | G2: conversation_id
A3: =CONCATENATE("TC_",'API Test Inputs'!A3,"_",'API Test Inputs'!B3,"_Description:",'API Test Inputs'!E3,"_Tester:",'API Test Inputs'!C3) -> TC_2_AI_Chat_Description:verifyCreateMessage_Tester:Alok Kumar | B3: ='API Test Inputs'!D3 -> /genai/graphql | C3: ='API Test Inputs'!F3 -> POST | D3: ='API Test Inputs'!G3 -> {"query":"mutation MyMutation { create_message( input: {prompt: \"{\\\"task\\\": \\\"\\\", \\\"scope\\\": \\\"\\\", \\\"context\\\": \\\"\\\", \\\"user_text\\\": \\\"What is PIC?\\\", \\\"custom_instruction\\\": \\\"\\\"}\", response: \"{\\\"long_response\\\": {\\\"graph\\\": [], \\\"table\\\": []}, \\\"short_response\\\": \\\"## Predictive Insights Center (PIC)\\\\n\\\\nThe **Predictive Insights Center (PIC)** is a strategic initiative driving Takeda's digital transformation through:\\\\n\\\\n- **Centralized Data Platform**: Unifies data from GMS/GQ systems into one source\\\\n- **AI Integration**: Provides automated, AI-driven prescriptive analytics\\\\n- **Cross-Functional Collaboration**: Bridges data silos between teams and departments\\\\n- **Decision Support**: Enables proactive, predictive decision-making\\\\n\\\\n### Key Features:\\\\n- Replaces fragmented tools with integrated digital solutions\\\\n- Facilitates end-to-end process orchestration\\\\n- Embeds AI for advanced predictive analytics\\\\n- Aims for faster, smarter operational decisions\\\\n\\\\n*Vision 2030 Goal*: Establish a single-source-of-truth environment for enterprise-wide insights.\\\", \\\"reasoning_response\\\": \\\"\\\"}\", prompt_datetime: \"{current_timeStamp}\", response_datetime: \"{current_timeStamp}\", prompt_emp_id: 50395262, conversation_id: \"{conversation_id}\", task_id: \"cc5f121d-f478-4f83-a88e-f092ae29e921\"} ) { message status data { message_id prompt response task_id user_rating conversation_id } }}"} | E3: ='API Test Inputs'!H3 -> 200 | F3: ='API Test Inputs'!I3 -> {"data":{"create_message":{"message":"Message created successfully","status":"Created","data":[{"message_id":"{message_id}","prompt":{"task":"","scope":"","context":"","user_text":"What is PIC?","custom_instruction":""},"response":{"long_response":{"graph":[],"table":[]},"reasoning_response":""},"task_id":"cc5f121d-f478-4f83-a88e-f092ae29e921","conversation_id":"{conversation_id}"}]}}} | G3: message_id
A4: =CONCATENATE("TC_",'API Test Inputs'!A4,"_",'API Test Inputs'!B4,"_Description:",'API Test Inputs'!E4,"_Tester:",'API Test Inputs'!C4) -> TC_3_AI_Chat_Description:verifyFetchConversation_Tester:Alok Kumar | B4: ='API Test Inputs'!D4 -> /genai/graphql | C4: ='API Test Inputs'!F4 -> POST | D4: ='API Test Inputs'!G4 -> {"operationName":"GetConversationName","variables":{},"query":"query GetConversationName {\n fetch_conversations(\n conversation_ids: \"{conversation_id}\"\n for_current_user: true\n scope_id: \"04b7fc60-63bd-44d7-bcbf-09d1476fa0aa\"\n ) {\n conversations {\n conversation_id\n conversation_name\n __typename\n }\n __typename\n }\n}"} | E4: ='API Test Inputs'!H4 -> 200 | F4: ='API Test Inputs'!I4 -> {"data":{"fetch_conversations":{"conversations":[{"conversation_id":"{conversation_id}","__typename":"Conversation"}],"__typename":"PaginatedConversations"}}}
A5: =CONCATENATE("TC_",'API Test Inputs'!A5,"_",'API Test Inputs'!B5,"_Description:",'API Test Inputs'!E5,"_Tester:",'API Test Inputs'!C5) -> TC_4_AI_Chat_Description:verifyFetchMessage_Tester:Alok Kumar | B5: ='API Test Inputs'!D5 -> /genai/graphql | C5: ='API Test Inputs'!F5 -> POST | D5: ='API Test Inputs'!G5 -> {"operationName":"UserGroupMemberId","variables":{},"query":"query UserGroupMemberId {\n fetch_messages(\n conversation_ids: [\"{conversation_id}\"]\n for_current_user: true\n task_id: \"cc5f121d-f478-4f83-a88e-f092ae29e921\"\n ) {\n messages {\n message_id\n conversation_id\n prompt\n prompt_created_ts\n response\n response_created_ts\n src_type\n user_rating\n prompted_by_emp_id\n gen_ai_audit\n task_id\n __typename\n }\n page_info {\n has_next_page\n has_previous_page\n start_cursor\n end_cursor\n __typename\n }\n __typename\n }\n}"} | E5: ='API Test Inputs'!H5 -> 200 | F5: ='API Test Inputs'!I5 -> {"data":{"fetch_messages":{"messages":[{"message_id":"{message_id}","conversation_id":"{conversation_id}","prompt":{"task":"","scope":"","context":"","user_text":"What is PIC?","custom_instruction":""},"response":{"long_response":{"graph":[],"table":[]},"reasoning_response":""},"src_type":"GEN_AI","prompted_by_emp_id":"50395262","task_id":"cc5f121d-f478-4f83-a88e-f092ae29e921"}],"page_info":{"has_next_page":false,"has_previous_page":false}}}}
A6: =CONCATENATE("TC_",'API Test Inputs'!A6,"_",'API Test Inputs'!B6,"_Description:",'API Test Inputs'!E6,"_Tester:",'API Test Inputs'!C6) -> TC_5_AI_Chat_Description:verifyUpdateConversation_Tester:Alok Kumar | B6: ='API Test Inputs'!D6 -> /genai/graphql | C6: ='API Test Inputs'!F6 -> POST | D6: ='API Test Inputs'!G6 -> {"operationName":"UpdateConversation","variables":{},"query":"mutation UpdateConversation {\n update_conversation(\n inputs: {scope_id: \"04b7fc60-63bd-44d7-bcbf-09d1476fa0aa\", conversation_name: \"Updated Conv by Automation\", conversation_id: \"{conversation_id}\"}\n ) {\n message\n status\n __typename\n }\n}"} | E6: ='API Test Inputs'!H6 -> 200 | F6: ='API Test Inputs'!I6 -> {"data":{"update_conversation":{"message":"Conversation updated successfully","status":"Updated","__typename":"ConversationResponse"}}}
A7: =CONCATENATE("TC_",'API Test Inputs'!A7,"_",'API Test Inputs'!B7,"_Description:",'API Test Inputs'!E7,"_Tester:",'API Test Inputs'!C7) -> TC_6_AI_Chat_Description:verifyUpdateMessage_Tester:Alok Kumar | B7: ='API Test Inputs'!D7 -> /genai/graphql | C7: ='API Test Inputs'!F7 -> POST | D7: ='API Test Inputs'!G7 -> {"operationName":"MyMutation","variables":{},"query":"mutation MyMutation {\n update_message(\n input: {message_id: \"{message_id}\", user_rating: 3}\n ) {\n data {\n conversation_id\n user_rating\n message_id\n task_id\n __typename\n }\n message\n status\n __typename\n }\n}"} | E7: ='API Test Inputs'!H7 -> 200 | F7: ='API Test Inputs'!I7 -> {"data":{"update_message":{"data":[{"conversation_id":"{conversation_id}","user_rating":3,"message_id":"{message_id}","task_id":"cc5f121d-f478-4f83-a88e-f092ae29e921","__typename":"MessageResponse"}],"message":"Message updated successfully","status":"Updated","__typename":"StandardResponse"}}}

Sheet NMT
A1: TestCaseName | B1: EndPoint | C1: Method | D1: Payload | E1: ExpectedStatusCode | F1: Expected Response | G1: Extracted Key
A2: TC_CreateScenario | B2: /nmt/api/v1/nmt/scenarios/ | C2: POST | D2: { "no_advance_calculation": false, "scenario_name": "Test-API-Automation", "scenario_description": "test", "users": [], "access_level": "private", "forecast_version": "2026-JAN", "start_date": "2026-JAN", "end_date": "2026-DEC", "flows": [ { "nodes": [ { "site_id": "3623", "description": "3623 - MFCT Lessines, Lessines (MFCT)" }, { "site_id": "7807", "description": "7807 - LOC Canada, Halton Hills (LOC)" } ], "index": "PLASMA:5500736 - CUVITRU,10G,CA:Canada:Cold:NO:B2B:3623|7807", "routed_nodes": [ "3623", "7807" ], "market_iso2": "CA", "trade_name": "CUVITRU", "operating_unit": "PLASMA", "temperature_range": "Cold", "controlled_drugs": "NO", "plm_status": "B2B", "sku_description": "5500736-CUVITRU,10G,CA", "country_description": "Canada", "gross_weight": 147, "quantity_per_pal": 1600, "material_text": "CUVITRU,10G,CA", "customer_code_in_ibp": "D_CA HM_DI_3032", "finance_country_code": "CA", "unit_of_measure": "PC", "material_type": "S - Finished Goods", "weight_unit": "G", "material_clean": "5500736", "temperature_detailed": "+2°C to +8°C", "distrib_sites": "3623|7807", "quantity_demand": [ { "lane_id": "3623_7807", "volume": 69049 } ], "quantity_supply": [ { "lane_id": "3623_7807", "volume": 77470.70031738281 } ], "flow_type": "Scope", "flow_key": 5225, "tariff_details": [ { "lane_id": "3623_7807", "country_code": "BE", "tariff_code": "3002150000", "unit_price": null, "currency": null, "total_price": 0, "tariff_rate_pct": 0, "tariff_rate_annex_1": null, "tariff_rate_annex_2": null, "tariff_duty": 0, "volume": 77470.70031738281 } ] }, { "nodes": [ { "site_id": "1501", "description": "1501 - MFCT Bray, Bray (MFCT)" }, { "site_id": "3801", "description": "3801 - RDC Germany Arvato, Harsewinkel (RDC)" }, { "site_id": "SA", "description": "Saudi arabia Wholes./Cust." } ], "index": "SM&O:6522110 - Fruzaqla 1mg 21ct Bottle KSA:Saudi Arabia:Ambient:NO:B2B:1501|3801|SA", "routed_nodes": [ "1501", "3801", "SA" ], "market_iso2": "SA", "trade_name": "FRUZAQLA", "operating_unit": "SM&O", "temperature_range": "Ambient", "controlled_drugs": "NO", "plm_status": "B2B", "sku_description": "6522110-Fruzaqla 1mg 21ct Bottle KSA", "country_description": "Saudi Arabia", "gross_weight": 41, "quantity_per_pal": 1200, "material_text": "Fruzaqla 1mg 21ct Bottle KSA", "customer_code_in_ibp": "D_SA OP_EP_1380", "finance_country_code": "SA", "unit_of_measure": "PC", "material_type": "S - Finished Goods", "weight_unit": "G", "material_clean": "6522110", "temperature_detailed": "+15°C to +25°C", "distrib_sites": "1501|3801|SA", "quantity_demand": [ { "lane_id": "1501_3801", "volume": 30 }, { "lane_id": "3801_SA", "volume": 30 } ], "quantity_supply": [ { "lane_id": "1501_3801", "volume": 48 }, { "lane_id": "3801_SA", "volume": 30 } ], "flow_type": "Scope", "flow_key": 11, "tariff_details": [ { "lane_id": "1501_3801", "country_code": null, "tariff_code": "30049000", "unit_price": 0, "currency": "EUR", "total_price": 0, "tariff_rate_pct": null, "tariff_rate_annex_1": null, "tariff_rate_annex_2": null, "tariff_duty": 0, "volume": 48 } ] }, { "nodes": [ { "site_id": "3623", "description": "3623 - MFCT Lessines, Lessines (MFCT)" }, { "site_id": "350", "description": "350 - LOC Switzerland, Niederbipp (LOC)" } ], "index": "PLASMA:1800223 - IG Infusion 10%, 20G - Clinical Studies:Switzerland:Cold:NO:CLINICAL:3623|350", "routed_nodes": [ "3623", "350" ], "market_iso2": "CH", "trade_name": "GAMMAGARD KIOVIG LIQUID", "operating_unit": "PLASMA", "temperature_range": "Cold", "controlled_drugs": "NO", "plm_status": "CLINICAL", "sku_description": "1800223-IG Infusion 10%, 20G - Clinical Studies", "country_description": "Switzerland", "gross_weight": 368, "quantity_per_pal": 600, "material_text": "IG Infusion 10%, 20G - Clinical Studies", "customer_code_in_ibp": "D_CH OP_EP_8036", "finance_country_code": "CH", "unit_of_measure": "PC", "material_type": "S - Finished Goods", "weight_unit": "G", "material_clean": "1800223", "temperature_detailed": "+2°C to +8°C", "distrib_sites": "3623|350", "quantity_demand": [ { "lane_id": "3623_350", "volume": 3900 } ], "quantity_supply": [ { "lane_id": "3623_350", "volume": 1968.5742797851562 } ], "flow_type": "Scope", "flow_key": 12, "tariff_details": [ { "lane_id": "3623_350", "country_code": null, "tariff_code": null, "unit_price": null, "currency": null, "total_price": 0, "tariff_rate_pct": null, "tariff_rate_annex_1": null, "tariff_rate_annex_2": null, "tariff_duty": 0, "volume": 1968.5742797851562 } ] }, { "nodes": [ { "site_id": "3623", "description": "3623 - MFCT Lessines, Lessines (MFCT)" }, { "site_id": "3801", "description": "3801 - RDC Germany Arvato, Harsewinkel (RDC)" } ], "index": "PLASMA:1800226 - BULK PACK CUVITRU 20G:Germany:Cold:NO:CLINICAL:3623|3801", "routed_nodes": [ "3623", "3801" ], "market_iso2": "DE", "trade_name": "CUVITRU", "operating_unit": "PLASMA", "temperature_range": "Cold", "controlled_drugs": "NO", "plm_status": "CLINICAL", "sku_description": "1800226-BULK PACK CUVITRU 20G", "country_description": "Germany", "gross_weight": 206, "quantity_per_pal": 1440, "material_text": "BULK PACK CUVITRU 20G", "customer_code_in_ibp": "D_DE HM_DI_8012", "finance_country_code": "DE", "unit_of_measure": "PC", "material_type": "S - Finished Goods", "weight_unit": "G", "material_clean": "1800226", "temperature_detailed": "+2°C to +8°C", "distrib_sites": "3623|3801", "quantity_demand": [ { "lane_id": "3623_3801", "volume": 2300 } ], "quantity_supply": [ { "lane_id": "3623_3801", "volume": 1257.1471862792969 } ], "flow_type": "Scope", "flow_key": 13, "tariff_details": [ { "lane_id": "3623_3801", "country_code": null, "tariff_code": null, "unit_price": null, "currency": null, "total_price": 0, "tariff_rate_pct": null, "tariff_rate_annex_1": null, "tariff_rate_annex_2": null, "tariff_duty": 0, "volume": 1257.1471862792969 } ] }, { "nodes": [ { "site_id": "3623", "description": "3623 - MFCT Lessines, Lessines (MFCT)" }, { "site_id": "3811", "description": "3811 - RDC Germany TOF, Alzenau (RDC)" } ], "index": "BIOLOGICS:8800240 - ADVATE,HIGH,CLINICAL,BAX111:Germany:Cold:NO:CLINICAL:3623|3811", "routed_nodes": [ "3623", "3811" ], "market_iso2": "DE", "trade_name": "ADVATE", "operating_unit": "BIOLOGICS", "temperature_range": "Cold", "controlled_drugs": "NO", "plm_status": "CLINICAL", "sku_description": "8800240-ADVATE,HIGH,CLINICAL,BAX111", "country_description": "Germany", "gross_weight": 11, "quantity_per_pal": 12960, "material_text": "ADVATE,HIGH,CLINICAL,BAX111", "customer_code_in_ibp": "D_DE HM_DI_8036", "finance_country_code": "DE", "unit_of_measure": "PC", "material_type": "S - Finished Goods", "weight_unit": "G", "material_clean": "8800240", "temperature_detailed": "+2°C to +8°C", "distrib_sites": "3623|3811", "quantity_demand": [ { "lane_id": "3623_3811", "volume": 500 } ], "quantity_supply": [ { "lane_id": "3623_3811", "volume": 357.1428527832031 } ], "flow_type": "Scope", "flow_key": 14, "tariff_details": [ { "lane_id": "3623_3811", "country_code": null, "tariff_code": null, "unit_price": null, "currency": null, "total_price": 0, "tariff_rate_pct": null, "tariff_rate_annex_1": null, "tariff_rate_annex_2": null, "tariff_duty": 0, "volume": 357.1428527832031 } ] }, { "nodes": [ { "site_id": "3622", "description": "3622 - MFCT Vienna, Vienna (MFCT)" }, { "site_id": "3811", "description": "3811 - RDC Germany TOF, Alzenau (RDC)" } ], "index": "OTHER:6510365 - RADAMTS13,1500IU,BJIIHF,5ML,YL CLINICAL:Germany:Cold:NO:CLINICAL:3622|3811", "routed_nodes": [ "3622", "3811" ], "market_iso2": "DE", "trade_name": "OTHER BIOTHERAPEUTICS", "operating_unit": "OTHER", "temperature_range": "Cold", "controlled_drugs": "NO", "plm_status": "CLINICAL", "sku_description": "6510365-RADAMTS13,1500IU,BJIIHF,5ML,YL CLINICAL", "country_description": "Germany", "gross_weight": 13, "quantity_per_pal": 2014, "material_text": "RADAMTS13,1500IU,BJIIHF,5ML,YL CLINICAL", "customer_code_in_ibp": "D_DE HM_DI_8036", "finance_country_code": "DE", "unit_of_measure": "PC", "material_type": "S - Finished Goods", "weight_unit": "G", "material_clean": "6510365", "temperature_detailed": "+2°C to +8°C", "distrib_sites": "3622|3811", "quantity_demand": [ { "lane_id": "3622_3811", "volume": 14000 } ], "quantity_supply": [ { "lane_id": "3622_3811", "volume": 18000 } ], "flow_type": "Scope", "flow_key": 15, "tariff_details": [ { "lane_id": "3622_3811", "country_code": null, "tariff_code": null, "unit_price": null, "currency": null, "total_price": 0, "tariff_rate_pct": null, "tariff_rate_annex_1": null, "tariff_rate_annex_2": null, "tariff_duty": 0, "volume": 18000 } ] }, { "nodes": [ { "site_id": "3623", "description": "3623 - MFCT Lessines, Lessines (MFCT)" }, { "site_id": "3001", "description": "3001 - LOC Argentina, Olivos (LOC)" } ], "index": "PLASMA:1501302 - KIOVIG,10G,AR:Argentina:Cold:NO:CONSTRAINED:3623|3001", "routed_nodes": [ "3623", "3001" ], "market_iso2": "AR", "trade_name": "GAMMAGARD KIOVIG LIQUID", "operating_unit": "PLASMA", "temperature_range": "Cold", "controlled_drugs": "NO", "plm_status": "CONSTRAINED", "sku_description": "1501302-KIOVIG,10G,AR", "country_description": "Argentina", "gross_weight": 238, "quantity_per_pal": 1008, "material_text": "KIOVIG,10G,AR", "customer_code_in_ibp": "D_AR HM_DI_9730", "finance_country_code": "AR", "unit_of_measure": "PC", "material_type": "S - Finished Goods", "weight_unit": "G", "material_clean": "1501302", "temperature_detailed": "+2°C to +8°C", "distrib_sites": "3623|3001", "quantity_demand": [ { "lane_id": "3623_3001", "volume": 5900 } ], "quantity_supply": [ { "lane_id": "3623_3001", "volume": 11828.03384399414 } ], "flow_type": "Scope", "flow_key": 17, "tariff_details": [ { "lane_id": "3623_3001", "country_code": null, "tariff_code": null, "unit_price": null, "currency": null, "total_price": 0, "tariff_rate_pct": null, "tariff_rate_annex_1": null, "tariff_rate_annex_2": null, "tariff_duty": 0, "volume": 11828.03384399414 } ] } ], "edited_flows": [], "reroute_flows": [], "lanes": [], "tariff_changes": [], "updated_lanes": [], "custom_node": [], "volume_type": "Supply" } | E2: 200 | F2: { "status": "Success", "data": { "scenario_id": "{scenario_id}" }, "error": null } | G2: scenario_id
A3: TC_SharedScenario | B3: /nmt/api/v1/nmt/scenarios/shared-scenario | C3: POST | D3: { "scenario_id": "{scenario_id}", "users": [ { "email_id": "soni.k-s@takeda.com", "user_name": "Soni K S [C]" } ] } | E3: 200 | F3: { "status": "Success", "data": { "message": "Email sent successfully" }, "error": null }
A4: TC_DeleteScenario | B4: /nmt/api/v1/nmt/scenarios?scenario_ids={scenario_id} | C4: DELETE | E4: 200 | F4: { "status": "Success", "data": { "message": "Record deleted successfully" }, "error": null }
A5: TC_GetScenarios | B5: /nmt/api/v1/nmt/scenarios/?is_historical=true | C5: GET | D5: {} | E5: 200 | F5: { "status": "Success", "data": { "scenarios": [ { "scenario_id": "scen-62a908e6066b4ab98021c3a3febcd9f5", "scenario_name": "Network overview - Nov 24 to Oct 25", "description": "Based on 12 months existing historical data", "markets": [ "Norway", "Argentina", "Kazakhstan", "Libya", "Panama", "Hong Kong", "Bulgaria", "Germany", "Ecuador", "Philippines", "Vietnam", "Croatia", "Kuwait", "Turkey", "Egypt", "France", "Czech Republic", "Belarus", "Finland", "Taiwan", "Estonia", "Denmark", "Singapore", "Russia", "Poland", "Colombia", "Serbia", "Costa Rica", "Brazil", "Mexico", "El Salvador", "Indonesia", "Paraguay", "South Africa", "New Zealand", "Slovakia", "Algeria", "Trinidad and Tobago", "Peru", "Switzerland", "Jordan", "Guatemala", "Slovenia", "Hungary", "Spain", "United States", "Ukraine", "Ireland", "Iraq", "Portugal", "Sweden", "Lithuania", "Honduras", "Lebanon", "Belgium", "Chile", "Romania", "Iran", "Canada", "Japan", "UK", "Tunisia", "Uruguay", "Netherlands", "Saudi Arabia", "Latvia", "Oman", "Bahrain", "Austria", "Italy", "Sri Lanka", "Thailand", "United Arab Emirates", "Israel", "Greece", "Azerbaijan", "India", "China", "Malaysia", "Australia" ], "brands": [ "TAKHZYRO", "ADVATE", "AFIPRAN", "ACTOVEGIN", "LEUPRORELIN", "CALCIUM", "MELATONINA", "GLYCOSTIGMIN", "QDENGA", "BRENTUXIMAB", "GUTRON", "PRUCALOPRIDE", "LANSOPRAZOLE", "PREDNISOLON", "OBIZUR", "VPRIV", "ASAFLOW", "VONOPRAZAN", "FLEXBUMIN", "FACTOR VII", "ADYNOVATE", "ASACOL", "LANTHANUM", "PONATINIB", "CUVITRU", "FUROSEMID", "NORIPURUM", "ICATIBANT", "ATROPIN", "VORTIOXETINE", "GYNIPRAL", "ALBYL-E", "IMMUNATE", "AT-III", "ELAPRASE", "LISDEXAMFETAMINE", "ARALAST", "DOPAMIN", "RIOPAN", "VITAMIN B12", "AZILSARTAN MEDOXOMIL", "PANTOPRAZOLE", "PIOGLITAZONE", "CINRYZE", "GATTEX/REVESTIVE", "XEFO", "NYCOPLUS", "LIQUID HYQVIA", "ALOGLIPTIN", "OTHER BIOTHERAPEUTICS", "BRIGATINIB", "IXAZOMIB", "RECOMBINATE", "ANAGRELIDE", "CIRCADINE", "DEXLANSOPRAZOLE", "FLOWEASE", "GLASSIA", "MISCELLANEOUS PRODUCTS", "RAMELTEON", "REPLAGAL", "MESALAZINE", "VONVENDI", "HYDROCOBAMIN", "RIXUBIS", "FAKTU", "-", "LYSTHENON", "CONDYLINE", "FEIBA", "LEVOTHYROXIN", "KLORAMFENIKOL", "EUPHYLLIN", "GAMMAGARD", "WARFARIN", "ADZYNMA", "ADRENALIN", "HYDROCORTISONE", "ADDERALL XR", "PROTHROMBIN", "VEDOLIZUMAB", "POLICRESULEN", "MAGNYL", "LIQUID IGIV", "MEPACT", "CEDOCARD", "MARIBAVIR", "IMMUNINE", "PROTEIN C", "FERRUM", "GEWACALM", "ALBUMIN NG", "OTHER", "FRUQUINTINIB", "GUANFACINE", "EBRANTIL" ], "market_count": 80, "brand_count": 96, "forecast_version": "", "start_date": "2024-NOV", "end_date": "2025-OCT", "scoring_available": "processing", "users": [], "created_by": { "user_name": "PIC_NMT_SERVICE", "image_url": "" }, "created_at": "2026-01-27T16:44:23.625816", "access_level": "global", "shared_with_user_emails": [], "volume_type": "Supply", "scen_stat_desc": "SUCCESS", "material_type": [ "RAW", "PACK", "TRAD", "HALB", "FINI" ] }, { "scenario_id": "scen-b938fc96a1e348188c6a77ea5ce5139e", "scenario_name": "Network overview - Dec 24 to Nov 25", "description": "Based on 12 months existing historical data", "markets": [ "Norway", "Argentina", "Kazakhstan", "Libya", "Panama", "Hong Kong", "Bulgaria", "Germany", "Ecuador", "Philippines", "Vietnam", "Croatia", "Kuwait", "Turkey", "Egypt", "France", "Czech Republic", "Belarus", "Finland", "Taiwan", "Estonia", "Denmark", "Singapore", "Russia", "Poland", "Colombia", "Serbia", "Costa Rica", "Brazil", "Mexico", "El Salvador", "Indonesia", "Paraguay", "South Africa", "New Zealand", "Slovakia", "Algeria", "Trinidad and Tobago", "Peru", "Switzerland", "Jordan", "Guatemala", "Slovenia", "Hungary", "Spain", "United States", "Ukraine", "Ireland", "Iraq", "Portugal", "Sweden", "Lithuania", "Honduras", "Lebanon", "Belgium", "Chile", "Romania", "Iran", "Canada", "Japan", "UK", "Tunisia", "Uruguay", "Netherlands", "Saudi Arabia", "Latvia", "Oman", "Bahrain", "Austria", "Italy", "Sri Lanka", "Thailand", "United Arab Emirates", "Israel", "Greece", "Azerbaijan", "India", "China", "Malaysia", "Australia" ], "brands": [ "TAKHZYRO", "ADVATE", "AFIPRAN", "ACTOVEGIN", "LEUPRORELIN", "CALCIUM", "MELATONINA", "GLYCOSTIGMIN", "QDENGA", "BRENTUXIMAB", "GUTRON", "PRUCALOPRIDE", "LANSOPRAZOLE", "PREDNISOLON", "OBIZUR", "VPRIV", "ASAFLOW", "VONOPRAZAN", "FLEXBUMIN", "FACTOR VII", "ADYNOVATE", "ASACOL", "LANTHANUM", "PONATINIB", "CUVITRU", "FUROSEMID", "NORIPURUM", "ICATIBANT", "ATROPIN", "VORTIOXETINE", "GYNIPRAL", "ALBYL-E", "IMMUNATE", "AT-III", "ELAPRASE", "LISDEXAMFETAMINE", "ARALAST", "DOPAMIN", "RIOPAN", "VITAMIN B12", "AZILSARTAN MEDOXOMIL", "PANTOPRAZOLE", "PIOGLITAZONE", "CINRYZE", "GATTEX/REVESTIVE", "XEFO", "NYCOPLUS", "LIQUID HYQVIA", "ALOGLIPTIN", "OTHER BIOTHERAPEUTICS", "BRIGATINIB", "IXAZOMIB", "RECOMBINATE", "ANAGRELIDE", "CIRCADINE", "DEXLANSOPRAZOLE", "FLOWEASE", "GLASSIA", "MISCELLANEOUS PRODUCTS", "RAMELTEON", "REPLAGAL", "MESALAZINE", "VONVENDI", "HYDROCOBAMIN", "RIXUBIS", "FAKTU", "-", "LYSTHENON", "CONDYLINE", "FEIBA", "LEVOTHYROXIN", "KLORAMFENIKOL", "EUPHYLLIN", "GAMMAGARD", "WARFARIN", "ADZYNMA", "ADRENALIN", "HYDROCORTISONE", "ADDERALL XR", "PROTHROMBIN", "VEDOLIZUMAB", "POLICRESULEN", "MAGNYL", "LIQUID IGIV", "MEPACT", "CEDOCARD", "MARIBAVIR", "IMMUNINE", "PROTEIN C", "FERRUM", "GEWACALM", "ALBUMIN NG", "OTHER", "FRUQUINTINIB", "GUANFACINE", "EBRANTIL" ], "market_count": 80, "brand_count": 96, "forecast_version": "", "start_date": "2024-DEC", "end_date": "2025-NOV", "scoring_available": "processing", "users": [], "created_by": { "user_name": "PIC_NMT_SERVICE", "image_url": "" }, "created_at": "2026-01-27T16:49:20.845209", "access_level": "global", "shared_with_user_emails": [], "volume_type": "Supply", "scen_stat_desc": "SUCCESS", "material_type": [ "RAW", "PACK", "TRAD", "HALB", "FINI" ] }, { "scenario_id": "scen-0d30009c947f45c38dd40849c606a362", "scenario_name": "Network overview - Jan 25 to Dec 25", "description": "Based on 12 months existing historical data", "markets": [ "Norway", "Argentina", "Kazakhstan", "Libya", "Panama", "Hong Kong", "Bulgaria", "Germany", "Ecuador", "Philippines", "Vietnam", "Croatia", "Kuwait", "Turkey", "Egypt", "France", "Czech Republic", "Belarus", "Finland", "Taiwan", "Estonia", "Denmark", "Singapore", "Russia", "Poland", "Colombia", "Serbia", "Costa Rica", "Brazil", "Mexico", "El Salvador", "Indonesia", "Paraguay", "South Africa", "New Zealand", "Slovakia", "Algeria", "Trinidad and Tobago", "Peru", "Switzerland", "Jordan", "Guatemala", "Slovenia", "Hungary", "Spain", "United States", "Ukraine", "Ireland", "Iraq", "Portugal", "Sweden", "Lithuania", "Honduras", "Lebanon", "Belgium", "Chile", "Romania", "Iran", "Canada", "Japan", "UK", "Tunisia", "Uruguay", "Netherlands", "Saudi Arabia", "Latvia", "Oman", "Bahrain", "Austria", "Italy", "Sri Lanka", "Thailand", "United Arab Emirates", "Israel", "Greece", "Azerbaijan", "India", "China", "Malaysia", "Australia" ], "brands": [ "TAKHZYRO", "ADVATE", "AFIPRAN", "ACTOVEGIN", "LEUPRORELIN", "CALCIUM", "MELATONINA", "GLYCOSTIGMIN", "QDENGA", "BRENTUXIMAB", "GUTRON", "PRUCALOPRIDE", "LANSOPRAZOLE", "PREDNISOLON", "OBIZUR", "VPRIV", "ASAFLOW", "VONOPRAZAN", "FLEXBUMIN", "FACTOR VII", "ADYNOVATE", "ASACOL", "LANTHANUM", "PONATINIB", "CUVITRU", "FUROSEMID", "NORIPURUM", "ICATIBANT", "ATROPIN", "VORTIOXETINE", "GYNIPRAL", "ALBYL-E", "IMMUNATE", "AT-III", "ELAPRASE", "LISDEXAMFETAMINE", "ARALAST", "DOPAMIN", "RIOPAN", "VITAMIN B12", "AZILSARTAN MEDOXOMIL", "PANTOPRAZOLE", "ALBETOL", "CINRYZE", "PIOGLITAZONE", "GATTEX/REVESTIVE", "XEFO", "NYCOPLUS", "LIQUID HYQVIA", "ALOGLIPTIN", "OTHER BIOTHERAPEUTICS", "BRIGATINIB", "IXAZOMIB", "RECOMBINATE", "ANAGRELIDE", "CIRCADINE", "DEXLANSOPRAZOLE", "FLOWEASE", "GLASSIA", "MISCELLANEOUS PRODUCTS", "RAMELTEON", "REPLAGAL", "MESALAZINE", "VONVENDI", "HYDROCOBAMIN", "RIXUBIS", "FAKTU", "-", "LYSTHENON", "CONDYLINE", "FEIBA", "LEVOTHYROXIN", "KLORAMFENIKOL", "EUPHYLLIN", "GAMMAGARD", "WARFARIN", "ADZYNMA", "ADRENALIN", "HYDROCORTISONE", "ADDERALL XR", "PROTHROMBIN", "VEDOLIZUMAB", "POLICRESULEN", "MAGNYL", "LIQUID IGIV", "MEPACT", "CEDOCARD", "MARIBAVIR", "IMMUNINE", "PROTEIN C", "FERRUM", "GEWACALM", "ALBUMIN NG", "OTHER", "FRUQUINTINIB", "GUANFACINE", "EBRANTIL" ], "market_count": 80, "brand_count": 97, "forecast_version": "", "start_date": "2025-JAN", "end_date": "2025-DEC", "scoring_available": "processing", "users": [], "created_by": { "user_name": "PIC_NMT_SERVICE", "image_url": "" }, "created_at": "2026-01-27T16:54:21.965650", "access_level": "global", "shared_with_user_emails": [], "volume_type": "Supply", "scen_stat_desc": "SUCCESS", "material_type": [ "RAW", "PACK", "TRAD", "HALB", "FINI" ] } ] }, "error": null }
A6: TC_GetScenario_By_Id | B6: /nmt/api/v1/nmt/scenarios/scenario_ids={scenario_id} | C6: GET | D6: {} | E6: 200 | F6: { "status": "Success", "data": { "is_baseline": true, "scenario_details": { "id": "{scenario_id}" "name": "Api_Automation", "description": "test", "forecast_version": "2026-JAN", "start_date": "2026-JAN", "end_date": "2026-DEC", "access_level_type_description": "restricted", "user_id": [ "soni.k-s@takeda.com", "naheeda.parveen@takeda.com" ] }, "score_details": { "cost_score": null, "co2_score": null, "leadtime_score": null, "final_score": null, "bc_score": null, "risk_score": null }, "artifact_data": { "lane_attributes": [ { "source": "517499", "sink": "3811", "lats": [ 51.98196029663086, 50.050270080566406 ], "lons": [ 19.91139030456543, 9.041939735412598 ], "color": "Site-RDC", "country_color": "Poland-Germany", "volume": 2836, "skus": 1, "sku_set": [ "1142668" ], "total_weight": 163.964, "transport_cost": 1209.9671021947238, "transport_cost_lo": 0, "transport_cost_up": 0, "transport_cost_road": 1209.9671021947238, "transport_cost_air": 0, "transport_cost_sea": 0, "transport_cost_warning_flag": false, "co2": 0.006623476157725194, "co2_road": 0.006623476157725194, "co2_air": 0, "co2_sea": 0, "num_shipments": 1, "controlled_shipments": 0, "cold_shipments": 0, "normal_shipments": 1, "num_shipments_air_amb": 0, "num_shipments_road_amb": 1, "num_shipments_sea_amb": 0, "num_shipments_air_cold": 0, "num_shipments_road_cold": 0, "num_shipments_sea_cold": 0, "volume_pallets": 1, "volume_air_amb": 0, "volume_road_amb": 1, "volume_sea_amb": 0, "volume_air_cold": 0, "volume_road_cold": 0, "volume_sea_cold": 0, "aws_road_flag": true, "sea_flag": true, "road_distance": 990.0960083007812, "sea_distance": 1166.69, "sea_road_part": 433.132, "air_distance": 993.3475704964529, "air_road_part": 134.593, "transp_lead_time_average": 1.9801920166015625, "lt_sea": 7.913088561403509, "lt_road": 1.9801920166015625, "lt_air": 2.3354091713664302, "certainty_score": 0.6930960086299892, "aggr_level_air_amb": null, "aggr_level_road_amb": "city->city", "aggr_level_sea_amb": null, "aggr_level_air_cold": null, "aggr_level_road_cold": null, "aggr_level_sea_cold": null, "consolidation_score": 0.8236914600550964, "has_road": true, "has_air": false, "has_sea": false, "u_description": "517499 - Orifarm Manufacturing Poland Sp. z, Lyszkowice", "v_description": "3811 - RDC Germany TOF, Alzenau, Trans-O-Flex", "u_city": "LYSZKOWICE, Poland", "v_city": "ALZENAU, Germany", "is_sanctioned_lane": false, "source_subregion": "Central-South Eastern Europe", "source_region": "EU & Canada", "destination_subregion": "Germany", "destination_region": "EU & Canada", "consolidated_air": 0, "consolidated_sea": 0, "consolidated_road": 0, "enforced_air": 0, "enforced_sea": 0, "enforced_road": 0, "source_closest_airports": null, "target_closest_airports": null, "source_closest_seaports": null, "target_closest_seaports": null, "ship_sol_weight": 0, "shipping_solutions": [], "suggested_shipping_solutions": [ { "ship_sol_std_nm": "csafe_rkn", "tot_shipped_pallets": 0, "ratio": 0, "ship_sol_cat": "Small Active Container", "full_ship_sol_nm": "cSafe RKN", "ship_sol_prop": 1, "temperature": "Ambient" }, { "ship_sol_std_nm": "blanket_ecosafe_plus", "tot_shipped_pallets": 0, "ratio": 0, "ship_sol_cat": "Thermal Blanket", "full_ship_sol_nm": "Thermal Blankets EcoSafe +", "ship_sol_prop": 0, "temperature": "Ambient" }, { "ship_sol_std_nm": "envirotainer_rkn_t2", "tot_shipped_pallets": 0, "ratio": 0, "ship_sol_cat": "Small Passive Container", "full_ship_sol_nm": "Envirotainer RKN T2", "ship_sol_prop": 0.5, "temperature": "Cold" }, { "ship_sol_std_nm": "envirotainer_rkn_e1", "tot_shipped_pallets": 0, "ratio": 0, "ship_sol_cat": "Small Active Container", "full_ship_sol_nm": "Envirotainer RKN E1", "ship_sol_prop": 0.5, "temperature": "Cold" }, { "ship_sol_std_nm": "envirotainer_rap_e2", "tot_shipped_pallets": 0, "ratio": 0, "ship_sol_cat": "Large Active Container", "full_ship_sol_nm": "Envirotainer RAP E2", "ship_sol_prop": 0, "temperature": "Cold" } ], "material_type": [ "T - Traded Goods" ], "origin_country": "Poland", "destination_country": "Germany", "volume_breakdown": [ { "volume": 2836, "unit": "PC" } ] }, { "source": "3811", "sink": "43", "lats": [ 50.050270080566406, 52.29304122924805 ], "lons": [ 9.041939735412598, 4.697000026702881 ], "color": "RDC-LOC", "country_color": "Germany-Netherlands", "volume": 4238.142868041992, "skus": 1, "sku_set": [ "1142668" ], "total_weight": 232.66900053405763, "transport_cost": 741.8847557432671, "transport_cost_lo": 0, "transport_cost_up": 0, "transport_cost_road": 741.8847557432671, "transport_cost_air": 0, "transport_cost_sea": 0, "transport_cost_warning_flag": false, "co2": 0.004606095120276595, "co2_road": 0.004606095120276595, "co2_air": 0, "co2_sea": 0, "num_shipments": 1, "controlled_shipments": 0, "cold_shipments": 0, "normal_shipments": 1, "num_shipments_air_amb": 0, "num_shipments_road_amb": 1, "num_shipments_sea_amb": 0, "num_shipments_air_cold": 0, "num_shipments_road_cold": 0, "num_shipments_sea_cold": 0, "volume_pallets": 1, "volume_air_amb": 0, "volume_road_amb": 1, "volume_sea_amb": 0, "volume_air_cold": 0, "volume_road_cold": 0, "volume_sea_cold": 0, "aws_road_flag": true, "sea_flag": true, "road_distance": 485.2149963378906, "sea_distance": 403.134, "sea_road_part": 502.06100000000004, "air_distance": 460.7411613109879, "air_road_part": 64.27091748867335, "transp_lead_time_average": 0.9704299926757812, "lt_sea": 6.7113746315789475, "lt_road": 0.9704299926757812, "lt_air": 2.159257912398079, "certainty_score": 0.29817286947141314, "aggr_level_air_amb": null, "aggr_level_road_amb": "city->country", "aggr_level_sea_amb": null, "aggr_level_air_cold": null, "aggr_level_road_cold": null, "aggr_level_sea_cold": null, "consolidation_score": 0.5075757575757576, "has_road": true, "has_air": false, "has_sea": false, "u_description": "3811 - RDC Germany TOF, Alzenau, Trans-O-Flex", "v_description": "43 - LOC Netherlands, EDE", "u_city": "ALZENAU, Germany", "v_city": "EDE, Netherlands", "is_sanctioned_lane": false, "source_subregion": "Germany", "source_region": "EU & Canada", "destination_subregion": "Central-South Eastern Europe", "destination_region": "EU & Canada", "consolidated_air": 0, "consolidated_sea": 0, "consolidated_road": 0, "enforced_air": 0, "enforced_sea": 0, "enforced_road": 0, "source_closest_airports": null, "target_closest_airports": null, "source_closest_seaports": null, "target_closest_seaports": null, "ship_sol_weight": 0, "shipping_solutions": [], "suggested_shipping_solutions": [ { "ship_sol_std_nm": "csafe_rkn", "tot_shipped_pallets": 0, "ratio": 0, "ship_sol_cat": "Small Active Container", "full_ship_sol_nm": "cSafe RKN", "ship_sol_prop": 1, "temperature": "Ambient" }, { "ship_sol_std_nm": "blanket_ecosafe_plus", "tot_shipped_pallets": 0, "ratio": 0, "ship_sol_cat": "Thermal Blanket", "full_ship_sol_nm": "Thermal Blankets EcoSafe +", "ship_sol_prop": 0, "temperature": "Ambient" }, { "ship_sol_std_nm": "envirotainer_rkn_t2", "tot_shipped_pallets": 0, "ratio": 0, "ship_sol_cat": "Small Passive Container", "full_ship_sol_nm": "Envirotainer RKN T2", "ship_sol_prop": 0.5, "temperature": "Cold" }, { "ship_sol_std_nm": "envirotainer_rkn_e1", "tot_shipped_pallets": 0, "ratio": 0, "ship_sol_cat": "Small Active Container", "full_ship_sol_nm": "Envirotainer RKN E1", "ship_sol_prop": 0.5, "temperature": "Cold" }, { "ship_sol_std_nm": "envirotainer_rap_e2", "tot_shipped_pallets": 0, "ratio": 0, "ship_sol_cat": "Large Active Container", "full_ship_sol_nm": "Envirotainer RAP E2", "ship_sol_prop": 0, "temperature": "Cold" } ], "material_type": [ "T - Traded Goods" ], "origin_country": "Germany", "destination_country": "Netherlands", "volume_breakdown": [ { "volume": 4238.142868041992, "unit": "PC" } ] }, { "source": "20", "sink": "LU", "lats": [ 50.89282989501953, 49.815868 ], "lons": [ 4.462500095367432, 6.129675 ], "color": "LOC-Wholes./Distrib.", "country_color": "Belgium-Luxembourg", "volume": 36681, "skus": 1, "sku_set": [ "6062079" ], "total_weight": 985.2579999999999, "transport_cost": 2893.398652021412, "transport_cost_lo": 0, "transport_cost_up": 0, "transport_cost_road": 2893.398652021412, "transport_cost_air": 0, "transport_cost_sea": 0, "transport_cost_warning_flag": false, "co2": 0.02072473434099191, "co2_road": 0.02072473434099191, "co2_air": 0, "co2_sea": 0, "num_shipments": 7, "controlled_shipments": 0, "cold_shipments": 0, "normal_shipments": 7, "num_shipments_air_amb": 0, "num_shipments_road_amb": 7, "num_shipments_sea_amb": 0, "num_shipments_air_cold": 0, "num_shipments_road_cold": 0, "num_shipments_sea_cold": 0, "volume_pallets": 13, "volume_air_amb": 0, "volume_road_amb": 13, "volume_sea_amb": 0, "volume_air_cold": 0, "volume_road_cold": 0, "volume_sea_cold": 0, "aws_road_flag": true, "sea_flag": true, "road_distance": 203.09921823018118, "sea_distance": 70.418, "sea_road_part": 222.9862289968481, "air_distance": 262.89618669230276, "air_road_part": 126.43299999999999, "transp_lead_time_average": 0.4061984364603624, "lt_sea": 5.569512808870889, "lt_road": 0.40619843646036236, "lt_air": 2.2703924124461534, "certainty_score": 0.266647996016928, "aggr_level_air_amb": null, "aggr_level_road_amb": "country->subregion", "aggr_level_sea_amb": null, "aggr_level_air_cold": null, "aggr_level_road_cold": null, "aggr_level_sea_cold": null, "consolidation_score": 0.19450056116722786, "has_road": true, "has_air": false, "has_sea": false, "u_description": "20 - LOC Belgium, Beersel(Lot)", "v_description": "Luxembourg Wholes./Cust.", "u_city": "BEERSEL(LOT), Belgium", "v_city": ", Luxembourg", "is_sanctioned_lane": false, "source_subregion": "Central-South Eastern Europe", "source_region": "EU & Canada", "destination_subregion": "Central-South Eastern Europe", "destination_region": "EU & Canada", "consolidated_air": 0, "consolidated_sea": 0, "consolidated_road": 0, "enforced_air": 0, "enforced_sea": 0, "enforced_road": 0, "source_closest_airports": null, "target_closest_airports": null, "source_closest_seaports": null, "target_closest_seaports": null, "ship_sol_weight": 0, "shipping_solutions": [], "suggested_shipping_solutions": [ { "ship_sol_std_nm": "csafe_rkn", "tot_shipped_pallets": 0, "ratio": 0, "ship_sol_cat": "Small Active Container", "full_ship_sol_nm": "cSafe RKN", "ship_sol_prop": 1, "temperature": "Ambient" }, { "ship_sol_std_nm": "blanket_ecosafe_plus", "tot_shipped_pallets": 0, "ratio": 0, "ship_sol_cat": "Thermal Blanket", "full_ship_sol_nm": "Thermal Blankets EcoSafe +", "ship_sol_prop": 0, "temperature": "Ambient" }, { "ship_sol_std_nm": "envirotainer_rkn_t2", "tot_shipped_pallets": 0, "ratio": 0, "ship_sol_cat": "Small Passive Container", "full_ship_sol_nm": "Envirotainer RKN T2", "ship_sol_prop": 0.5, "temperature": "Cold" }, { "ship_sol_std_nm": "envirotainer_rkn_e1", "tot_shipped_pallets": 0, "ratio": 0, "ship_sol_cat": "Small Active Container", "full_ship_sol_nm": "Envirotainer RKN E1", "ship_sol_prop": 0.5, "temperature": "Cold" }, { "ship_sol_std_nm": "envirotainer_rap_e2", "tot_shipped_pallets": 0, "ratio": 0, "ship_sol_cat": "Large Active Container", "full_ship_sol_nm": "Envirotainer RAP E2", "ship_sol_prop": 0, "temperature": "Cold" } ], "material_type": [ "T - Traded Goods" ], "origin_country": "Belgium", "destination_country": "Luxembourg", "volume_breakdown": [ { "volume": 36681, "unit": "PC" } ] }, { "source": "3811", "sink": "100", "lats": [ 50.050270080566406, 55.628021240234375 ], "lons": [ 9.041939735412598, 12.385540008544922 ], "color": "RDC-LOC", "country_color": "Germany-Denmark", "volume": 0, "skus": 1, "sku_set": [ "6228081" ], "total_weight": 0, "transport_cost": 0, "transport_cost_lo": 0, "transport_cost_up": 0, "transport_cost_road": 0, "transport_cost_air": 0, "transport_cost_sea": 0, "transport_cost_warning_flag": false, "co2": 0, "co2_road": 0, "co2_air": 0, "co2_sea": 0, "num_shipments": 0, "controlled_shipments": 0, "cold_shipments": 0, "normal_shipments": 0, "num_shipments_air_amb": 0, "num_shipments_road_amb": 0, "num_shipments_sea_amb": 0, "num_shipments_air_cold": 0, "num_shipments_road_cold": 0, "num_shipments_sea_cold": 0, "volume_pallets": 0, "volume_air_amb": 0, "volume_road_amb": 0, "volume_sea_amb": 0, "volume_air_cold": 0, "volume_road_cold": 0, "volume_sea_cold": 0, "aws_road_flag": true, "sea_flag": true, "road_distance": 805.625, "sea_distance": 813.914, "sea_road_part": 756.268, "air_distance": 775.1073137575298, "air_road_part": 74.943, "transp_lead_time_average": 0, "lt_sea": 7.940455298245614, "lt_road": 1.61125, "lt_air": 2.2015598209171685, "certainty_score": 0, "aggr_level_air_amb": null, "aggr_level_road_amb": null, "aggr_level_sea_amb": null, "aggr_level_air_cold": null, "aggr_level_road_cold": null, "aggr_level_sea_cold": null, "consolidation_score": 0, "has_road": false, "has_air": false, "has_sea": false, "u_description": "3811 - RDC Germany TOF, Alzenau, Trans-O-Flex", "v_description": "100 - LOC Hobro & LOC Denmark, Køge", "u_city": "ALZENAU, Germany", "v_city": "KØGE, Denmark", "is_sanctioned_lane": false, "source_subregion": "Germany", "source_region": "EU & Canada", "destination_subregion": "Nordics", "destination_region": "EU & Canada", "consolidated_air": 0, "consolidated_sea": 0, "consolidated_road": 0, "enforced_air": 0, "enforced_sea": 0, "enforced_road": 0, "source_closest_airports": null, "target_closest_airports": null, "source_closest_seaports": null, "target_closest_seaports": null, "ship_sol_weight": 0, "shipping_solutions": [], "suggested_shipping_solutions": [ { "ship_sol_std_nm": "csafe_rkn", "tot_shipped_pallets": 0, "ratio": 0, "ship_sol_cat": "Small Active Container", "full_ship_sol_nm": "cSafe RKN", "ship_sol_prop": 1, "temperature": "Ambient" }, { "ship_sol_std_nm": "blanket_ecosafe_plus", "tot_shipped_pallets": 0, "ratio": 0, "ship_sol_cat": "Thermal Blanket", "full_ship_sol_nm": "Thermal Blankets EcoSafe +", "ship_sol_prop": 0, "temperature": "Ambient" }, { "ship_sol_std_nm": "envirotainer_rkn_t2", "tot_shipped_pallets": 0, "ratio": 0, "ship_sol_cat": "Small Passive Container", "full_ship_sol_nm": "Envirotainer RKN T2", "ship_sol_prop": 0.5, "temperature": "Cold" }, { "ship_sol_std_nm": "envirotainer_rkn_e1", "tot_shipped_pallets": 0, "ratio": 0, "ship_sol_cat": "Small Active Container", "full_ship_sol_nm": "Envirotainer RKN E1", "ship_sol_prop": 0.5, "temperature": "Cold" }, { "ship_sol_std_nm": "envirotainer_rap_e2", "tot_shipped_pallets": 0, "ratio": 0, "ship_sol_cat": "Large Active Container", "full_ship_sol_nm": "Envirotainer RAP E2", "ship_sol_prop": 0, "temperature": "Cold" } ], "material_type": [ "T - Traded Goods" ], "origin_country": "Germany", "destination_country": "Denmark", "volume_breakdown": [ { "volume": 0, "unit": "PC" } ] }, { "source": "20", "sink": "43", "lats": [ 50.89282989501953, 52.29304122924805 ], "lons": [ 4.462500095367432, 4.697000026702881 ], "color": "LOC-LOC", "country_color": "Belgium-Netherlands", "volume": 1575.1428451538086, "skus": 1, "sku_set": [ "1142668" ], "total_weight": 102.18199941253663, "transport_cost": 350.6365843319055, "transport_cost_lo": 0, "transport_cost_up": 0, "transport_cost_road": 350.6365843319055, "transport_cost_air": 0, "transport_cost_sea": 0, "transport_cost_warning_flag": false, "co2": 0.0008348431730577038, "co2_road": 0.0008348431730577038, "co2_air": 0, "co2_sea": 0, "num_shipments": 1, "controlled_shipments": 0, "cold_shipments": 0, "normal_shipments": 1, "num_shipments_air_amb": 0, "num_shipments_road_amb": 1, "num_shipments_sea_amb": 0, "num_shipments_air_cold": 0, "num_shipments_road_cold": 0, "num_shipments_sea_cold": 0, "volume_pallets": 1, "volume_air_amb": 0, "volume_road_amb": 1, "volume_sea_amb": 0, "volume_air_cold": 0, "volume_road_cold": 0, "volume_sea_cold": 0, "aws_road_flag": true, "sea_flag": true, "road_distance": 200.24899291992188, "sea_distance": 70.9654, "sea_road_part": 86.1042289968481, "air_distance": 252.6587978844417, "air_road_part": 16.030917488673353, "transp_lead_time_average": 0.40049798583984375, "lt_sea": 5.296709159748082, "lt_road": 0.40049798583984375, "lt_air": 2.0489057548363094, "certainty_score": 0.4011596548004314, "aggr_level_air_amb": null, "aggr_level_road_amb": "country->country", "aggr_level_sea_amb": null, "aggr_level_air_cold": null, "aggr_level_road_cold": null, "aggr_level_sea_cold": null, "consolidation_score": 0.20168350168350166, "has_road": true, "has_air": false, "has_sea": false, "u_description": "20 - LOC Belgium, Beersel(Lot)", "v_description": "43 - LOC Netherlands, EDE", "u_city": "BEERSEL(LOT), Belgium", "v_city": "EDE, Netherlands", "is_sanctioned_lane": false, "source_subregion": "Central-South Eastern Europe", "source_region": "EU & Canada", "destination_subregion": "Central-South Eastern Europe", "destination_region": "EU & Canada", "consolidated_air": 0, "consolidated_sea": 0, "consolidated_road": 0, "enforced_air": 0, "enforced_sea": 0, "enforced_road": 0, "source_closest_airports": null, "target_closest_airports": null, "source_closest_seaports": null, "target_closest_seaports": null, "ship_sol_weight": 0, "shipping_solutions": [], "suggested_shipping_solutions": [ { "ship_sol_std_nm": "csafe_rkn", "tot_shipped_pallets": 0, "ratio": 0, "ship_sol_cat": "Small Active Container", "full_ship_sol_nm": "cSafe RKN", "ship_sol_prop": 1, "temperature": "Ambient" }, { "ship_sol_std_nm": "blanket_ecosafe_plus", "tot_shipped_pallets": 0, "ratio": 0, "ship_sol_cat": "Thermal Blanket", "full_ship_sol_nm": "Thermal Blankets EcoSafe +", "ship_sol_prop": 0, "temperature": "Ambient" }, { "ship_sol_std_nm": "envirotainer_rkn_t2", "tot_shipped_pallets": 0, "ratio": 0, "ship_sol_cat": "Small Passive Container", "full_ship_sol_nm": "Envirotainer RKN T2", "ship_sol_prop": 0.5, "temperature": "Cold" }, { "ship_sol_std_nm": "envirotainer_rkn_e1", "tot_shipped_pallets": 0, "ratio": 0, "ship_sol_cat": "Small Active Container", "full_ship_sol_nm": "Envirotainer RKN E1", "ship_sol_prop": 0.5, "temperature": "Cold" }, { "ship_sol_std_nm": "envirotainer_rap_e2", "tot_shipped_pallets": 0, "ratio": 0, "ship_sol_cat": "Large Active Container", "full_ship_sol_nm": "Envirotainer RAP E2", "ship_sol_prop": 0, "temperature": "Cold" } ], "material_type": [ "T - Traded Goods" ], "origin_country": "Belgium", "destination_country": "Netherlands", "volume_breakdown": [ { "volume": 1575.1428451538086, "unit": "PC" } ] }, { "source": "143285", "sink": "3811", "lats": [ 32.110107421875, 50.050270080566406 ], "lons": [ 34.83861541748047, 9.041939735412598 ], "color": "Site-RDC", "country_color": "Israel-Germany", "volume": 1305955.30859375, "skus": 2, "sku_set": [ "6228081", "6062079" ], "total_weight": 104806.1955546875, "transport_cost": 370162.84511882346, "transport_cost_lo": 0, "transport_cost_up": 0, "transport_cost_road": 0, "transport_cost_air": 216990.7779739139, "transport_cost_sea": 153172.06714490947, "transport_cost_warning_flag": false, "co2": 166.4179686958179, "co2_road": 0, "co2_air": 163.9056468449986, "co2_sea": 2.512321850819271, "num_shipments": 56, "controlled_shipments": 0, "cold_shipments": 0, "normal_shipments": 56, "num_shipments_air_amb": 33, "num_shipments_road_amb": 0, "num_shipments_sea_amb": 23, "num_shipments_air_cold": 0, "num_shipments_road_cold": 0, "num_shipments_sea_cold": 0, "volume_pallets": 436, "volume_air_amb": 109, "volume_road_amb": 0, "volume_sea_amb": 327, "volume_air_cold": 0, "volume_road_cold": 0, "volume_sea_cold": 0, "aws_road_flag": true, "sea_flag": true, "road_distance": 4106.22021484375, "sea_distance": 6854.1, "sea_road_part": 478.504, "air_distance": 3049.2419650209126, "air_road_part": 78.319, "transp_lead_time_average": 14.076288830995964, "lt_sea": 17.981744842105265, "lt_road": 8.2124404296875, "lt_air": 2.3599207976680607, "certainty_score": 0.1579572160579442, "aggr_level_air_amb": "region->region", "aggr_level_road_amb": null, "aggr_level_sea_amb": "region->region", "aggr_level_air_cold": null, "aggr_level_road_cold": null, "aggr_level_sea_cold": null, "consolidation_score": 0.506424660120846, "has_road": false, "has_air": true, "has_sea": true, "u_description": "143285 - Neurim Pharmaceuticals (1991) Ltd., Tel Aviv", "v_description": "3811 - RDC Germany TOF, Alzenau, Trans-O-Flex", "u_city": "TEL AVIV, Israel", "v_city": "ALZENAU, Germany", "is_sanctioned_lane": false, "source_subregion": "Central-South Eastern Europe", "source_region": "EU & Canada", "destination_subregion": "Germany", "destination_region": "EU & Canada", "consolidated_air": 0, "consolidated_sea": 0, "consolidated_road": 0, "enforced_air": 0, "enforced_sea": 0, "enforced_road": 0, "source_closest_airports": null, "target_closest_airports": null, "source_closest_seaports": null, "target_closest_seaports": null, "ship_sol_weight": 70414, "shipping_solutions": [ { "ship_sol_std_nm": "csafe_rkn", "tot_shipped_pallets": 109, "ratio": 1, "ship_sol_cat": null, "full_ship_sol_nm": "cSafe RKN", "ship_sol_prop": 0, "temperature": null } ], "suggested_shipping_solutions": [ { "ship_sol_std_nm": "csafe_rkn", "tot_shipped_pallets": 0, "ratio": 0, "ship_sol_cat": "Small Active Container", "full_ship_sol_nm": "cSafe RKN", "ship_sol_prop": 1, "temperature": "Ambient" }, { "ship_sol_std_nm": "blanket_ecosafe_plus", "tot_shipped_pallets": 0, "ratio": 0, "ship_sol_cat": "Thermal Blanket", "full_ship_sol_nm": "Thermal Blankets EcoSafe +", "ship_sol_prop": 0, "temperature": "Ambient" }, { "ship_sol_std_nm": "envirotainer_rkn_t2", "tot_shipped_pallets": 0, "ratio": 0, "ship_sol_cat": "Small Passive Container", "full_ship_sol_nm": "Envirotainer RKN T2", "ship_sol_prop": 0.5, "temperature": "Cold" }, { "ship_sol_std_nm": "envirotainer_rkn_e1", "tot_shipped_pallets": 0, "ratio": 0, "ship_sol_cat": "Small Active Container", "full_ship_sol_nm": "Envirotainer RKN E1", "ship_sol_prop": 0.5, "temperature": "Cold" }, { "ship_sol_std_nm": "envirotainer_rap_e2", "tot_shipped_pallets": 0, "ratio": 0, "ship_sol_cat": "Large Active Container", "full_ship_sol_nm": "Envirotainer RAP E2", "ship_sol_prop": 0, "temperature": "Cold" } ], "material_type": [ "T - Traded Goods" ], "origin_country": "Israel", "destination_country": "Germany", "volume_breakdown": [ { "volume": 1305955.30859375, "unit": "PC" } ] }, { "source": "3811", "sink": "20", "lats": [ 50.050270080566406, 50.89282989501953 ], "lons": [ 9.041939735412598, 4.462500095367432
A7: TC_GetStatus | B7: /nmt/api/v1/status/ | C7: GET | D7: {} | E7: 200 | F7: { "message": "OK" }
A8: TC_Update_NmtScenario | B8: /nmt/api/v1/nmt/scenarios/{scenario_id} | C8: PATCH | D8: { "no_advance_calculation": true, "transport_lane_calculation": false, "scenario_name": "string", "scenario_description": "string", "users": [ "string" ], "access_level": "string", "forecast_version": "string", "start_date": "string", "end_date": "string", "volume_type": "Demand", "validation_params": { "lanes": [ { "source": "string", "sink": "string", "lats": [ 0 ], "lons": [ 0 ], "color": "string", "country_color": "string", "volume": 0, "skus": 0, "sku_set": "string", "total_weight": 0, "transport_cost": 0, "transport_cost_lo": 0, "transport_cost_up": 0, "transport_cost_road": 0, "transport_cost_air": 0, "transport_cost_sea": 0, "transport_cost_warning_flag": true, "co2": 0, "co2_road": 0, "co2_air": 0, "co2_sea": 0, "num_shipments": 0, "controlled_shipments": 0, "cold_shipments": 0, "normal_shipments": 0, "num_shipments_air_amb": 0, "num_shipments_road_amb": 0, "num_shipments_sea_amb": 0, "num_shipments_air_cold": 0, "num_shipments_road_cold": 0, "num_shipments_sea_cold": 0, "volume_pallets": 0, "volume_air_amb": 0, "volume_road_amb": 0, "volume_sea_amb": 0, "volume_air_cold": 0, "volume_road_cold": 0, "volume_sea_cold": 0, "aws_road_flag": true, "sea_flag": true, "road_distance": 0, "sea_distance": 0, "sea_road_part": 0, "air_distance": 0, "air_road_part": 0, "transp_lead_time_average": 0, "lt_sea": 0, "lt_road": 0, "lt_air": 0, "certainty_score": 0, "aggr_level_air_amb": "string", "aggr_level_road_amb": "string", "aggr_level_sea_amb": "string", "aggr_level_air_cold": "string", "aggr_level_road_cold": "string", "aggr_level_sea_cold": "string", "consolidation_score": 0, "has_road": true, "has_air": true, "has_sea": true, "u_description": "string", "v_description": "string", "u_city": "string", "v_city": "string", "is_sanctioned_lane": true, "source_subregion": "string", "source_region": "string", "destination_subregion": "string", "destination_region": "string", "consolidated_air": 0, "consolidated_sea": 0, "consolidated_road": 0, "enforced_air": 0, "enforced_sea": 0, "enforced_road": 0, "source_closest_airports": {}, "target_closest_airports": {}, "source_closest_seaports": {}, "target_closest_seaports": {}, "ship_sol_weight": 0, "shipping_solutions": [], "suggested_shipping_solutions": [], "material_type": [], "origin_country": "string", "destination_country": "string", "volume_breakdown": [] } ], "selected_rows": [ "string" ], "air_defined": 0, "sea_defined": 0, "road_defined": 0, "mode": "string", "consolidation": 0, "shipments_enforced": 0, "shipping_solutions": [] }, "flows": [ { "nodes": [ { "site_id": "string", "description": "string", "country": "string" } ], "routed_nodes": [ "string" ], "market_iso2": "string", "trade_name": "string", "operating_unit": "string", "temperature_range": "string", "controlled_drugs": "string", "plm_status": "string", "sku_description": "string", "country_description": "string", "gross_weight": 0, "quantity_per_pal": 0, "tariff_details": [], "quantity_demand": [ { "lane_id": "string", "volume": 0 } ], "quantity_supply": [ { "lane_id": "string", "volume": 0 } ], "material_text": "string", "customer_code_in_ibp": "string", "finance_country_code": "string", "unit_of_measure": "string", "material_type": "string", "weight_unit": "string", "material_clean": "string", "temperature_detailed": "string", "flow_type": "Scope", "region_description": "string", "sub_region_description": "string", "node_version_ids": [ "string" ], "distrib_sites": "string", "flow_key": 0, "index": "string", "distribuition_site_1": "", "distribuition_site_2": "", "distribuition_site_3": "", "distribuition_site_4": "", "distribuition_site_5": "" } ], "edited_flows": [ { "index": "string", "new_distrib_sites": "string" } ], "reroute_flows": [ { "template_index": [ "string" ], "mode": "string", "nodes": [ "string" ] } ], "lanes": [ { "from_lane": "string", "to_lane": "string", "temperature": "string", "air": 0, "road": 0, "sea": 0, "air_cons": 0, "road_cons": 0, "sea_cons": 0, "air_shipments": 0, "road_shipments": 0, "sea_shipments": 0, "air_ship_sol": { "additionalProp1": 0, "additionalProp2": 0, "additionalProp3": 0 } } ], "updated_lanes": [ { "updated_type": "string", "number_of_pallets": 0, "number_of_shipments": 0, "number_of_lanes": 0, "affected_rows": [ "string" ], "change": "string", "air_defined": 0, "sea_defined": 0, "road_defined": 0, "mode": "string", "consolidation": 0, "shipments_enforced": 0 } ], "custom_node": [ { "node_id": "string", "node_type": "string", "node_sub_type": "string", "node_country": "string", "node_postal_code": "string", "node_address": "string", "node_city": "string", "node_description": "string", "node_iso": "string", "node_latitude": 0, "node_longitude": 0, "distance_from_node": [ { "nodes": [ "string" ], "units_of_measure": "kilometer", "distance": 0 } ] } ], "tariff_changes": [], "warehouse_changes": { "brand": [ {} ], "node": [ {} ] } } | E8: 200 | F8: { "status": "Success", "data": { "scenario_id": "{scenario_id}" "task_id": "{task_id}", "message": "Record updated successfully", "details": null }, "error": null }
A9: TC_Get_Brands_Market | B9: /nmt/api/v1/nmt/scenarios/{scenario_id}/brands-markets?has_brands=true&has_markets=true | C9: GET | D9: {} | E9: 200 | F9: { "status": "Success", "data": { "scenario_details": { "brands": [ "OTHER BIOTHERAPEUTICS", "CUVITRU", "ADVATE", "GAMMAGARD KIOVIG LIQUID" ], "markets": [ "Argentina", "Switzerland", "Germany" ] } }, "error": null }

Sheet API Test Inputs
A1: TC No | B1: Team Name | C1: QE Resource | D1: EndPoint | E1: TestCaseName | F1: Method | G1: Payload | H1: ExpectedStatusCode | I1: Expected Response | J1: Extracted_Key
A2: 1 | B2: AI_Chat | C2: Alok Kumar | D2: /genai/graphql | E2: verifyCreateConversation | F2: POST | G2: {"query":"mutation MyMutation {\n create_conversation(\n inputs: {scope_id: \"04b7fc60-63bd-44d7-bcbf-09d1476fa0aa\", conversation_name: \"Created Conv by Automation\", conversation_id: \"{conversation_id}\", created_timestamp: \"{current_timeStamp}\", owned_by_user_id: 50395262, shared_by_user_id : 50395262}\n ) {\n data {\n conversation_id\n conv_own_emp_id\n conversation_name\n created_timestamp\n last_msg_timestamp\n scope_id\n shared_by_user_id\n }\n message\n status\n }\n}"} | H2: 200 | I2: {"data":{"create_conversation":{"data":[{"conversation_id":"{conversation_id}","conv_own_emp_id":50395262,"conversation_name":"Created Conv by Automation","scope_id":"04b7fc60-63bd-44d7-bcbf-09d1476fa0aa","shared_by_user_id":50395262}],"message":"Conversation created successfully","status":"Created"}}} | J2: conversation_id
A3: 2 | B3: AI_Chat | C3: Alok Kumar | D3: /genai/graphql | E3: verifyCreateMessage | F3: POST | G3: {"query":"mutation MyMutation { create_message( input: {prompt: \"{\\\"task\\\": \\\"\\\", \\\"scope\\\": \\\"\\\", \\\"context\\\": \\\"\\\", \\\"user_text\\\": \\\"What is PIC?\\\", \\\"custom_instruction\\\": \\\"\\\"}\", response: \"{\\\"long_response\\\": {\\\"graph\\\": [], \\\"table\\\": []}, \\\"short_response\\\": \\\"## Predictive Insights Center (PIC)\\\\n\\\\nThe **Predictive Insights Center (PIC)** is a strategic initiative driving Takeda's digital transformation through:\\\\n\\\\n- **Centralized Data Platform**: Unifies data from GMS/GQ systems into one source\\\\n- **AI Integration**: Provides automated, AI-driven prescriptive analytics\\\\n- **Cross-Functional Collaboration**: Bridges data silos between teams and departments\\\\n- **Decision Support**: Enables proactive, predictive decision-making\\\\n\\\\n### Key Features:\\\\n- Replaces fragmented tools with integrated digital solutions\\\\n- Facilitates end-to-end process orchestration\\\\n- Embeds AI for advanced predictive analytics\\\\n- Aims for faster, smarter operational decisions\\\\n\\\\n*Vision 2030 Goal*: Establish a single-source-of-truth environment for enterprise-wide insights.\\\", \\\"reasoning_response\\\": \\\"\\\"}\", prompt_datetime: \"{current_timeStamp}\", response_datetime: \"{current_timeStamp}\", prompt_emp_id: 50395262, conversation_id: \"{conversation_id}\", task_id: \"cc5f121d-f478-4f83-a88e-f092ae29e921\"} ) { message status data { message_id prompt response task_id user_rating conversation_id } }}"} | H3: 200 | I3: {"data":{"create_message":{"message":"Message created successfully","status":"Created","data":[{"message_id":"{message_id}","prompt":{"task":"","scope":"","context":"","user_text":"What is PIC?","custom_instruction":""},"response":{"long_response":{"graph":[],"table":[]},"reasoning_response":""},"task_id":"cc5f121d-f478-4f83-a88e-f092ae29e921","conversation_id":"{conversation_id}"}]}}} | J3: message_id
A4: 3 | B4: AI_Chat | C4: Alok Kumar | D4: /genai/graphql | E4: verifyFetchConversation | F4: POST | G4: {"operationName":"GetConversationName","variables":{},"query":"query GetConversationName {\n fetch_conversations(\n conversation_ids: \"{conversation_id}\"\n for_current_user: true\n scope_id: \"04b7fc60-63bd-44d7-bcbf-09d1476fa0aa\"\n ) {\n conversations {\n conversation_id\n conversation_name\n __typename\n }\n __typename\n }\n}"} | H4: 200 | I4: {"data":{"fetch_conversations":{"conversations":[{"conversation_id":"{conversation_id}","__typename":"Conversation"}],"__typename":"PaginatedConversations"}}}
